Workbook

Sheet Market Analysis
A1: Regional Share (%)
A2: North America | B2: 0.364 | E2: USD Millions | H2: On the basis of no test
A3: Europe | B3: 0.25 | D3: Global Base Number | E3: 5467 | H3: Population
A4: Asia Pacific | B4: 0.234 | H4: Disease
A5: Latin America | B5: 0.1 | F5: 0.145
A6: Middle East and Africa | B6: =1-SUM(B2:B5) -> 0.052
B7: =SUM(B2:B6) -> 1
C8: Historical | D8: Historical | E8: Base Year | F8: Estimated | G8: Forecast | H8: Forecast | I8: Forecast | J8: Forecast | K8: Forecast | L8: Forecast | M8: Forecast | N8: Forecast | O8: Forecast | P8: Forecast
C9: 2023 | D9: =C9+1 -> 2024 | E9: =D9+1 -> 2025 | F9: =E9+1 -> 2026 | G9: =F9+1 -> 2027 | H9: =G9+1 -> 2028 | I9: =H9+1 -> 2029 | J9: =I9+1 -> 2030 | K9: =J9+1 -> 2031 | ... P9: =O9+1 -> 2036 | Q9: CAGR % (2027-2036)
A10: North America | B10: =B2 -> 0.364 | C10: =B10*E3 -> 1989.988 | D10: =D12+D14 -> 2271.4121 | E10: =E12+E14 -> 2596.1078 | F10: =F12+F14 -> 2971.2332 | G10: =G12+G14 -> 3405.2109 | H10: =H12+H14 -> 3907.9649 | I10: =I12+I14 -> 4491.2043 | J10: =J12+J14 -> 5168.7645 | K10: =K12+K14 -> 5957.0163 | ... P10: =P12+P14 -> 12380.481 | Q10: =RATE(9,,-G10,P10) -> 0.15421886
D11: 0.142 | E11: 0.14356786 | F11: 0.14515304 | G11: 0.14675571 | H11: 0.14837608 | I11: 0.15001435 | J11: 0.1516707 | K11: 0.15334534 | L11: 0.15503846 | M11: 0.15675029 | N11: 0.15848101 | O11: 0.16023085 | P11: 0.162
A12: United States (92-97%) | B12: 0.942 | C12: =B12*C10 -> 1874.5687 | D12: =C12*(1+D11) -> 2140.7575 | E12: =D12*(1+E11) -> 2448.1014 | F12: =E12*(1+F11) -> 2803.4508 | G12: =F12*(1+G11) -> 3214.8732 | H12: =G12*(1+H11) -> 3691.8835 | I12: =H12*(1+I11) -> 4245.719 | J12: =I12*(1+J11) -> 4889.6701 | K12: =J12*(1+K11) -> 5639.4782 | ... P12: =O12*(1+P11) -> 11768.319 | Q12: =RATE(9,,-G12,P12) -> 0.15509242
D13: 0.132 | E13: 0.13280573 | F13: 0.13361637 | G13: 0.13443196 | H13: 0.13525253 | I13: 0.13607811 | J13: 0.13690873 | K13: 0.13774442 | L13: 0.13858521 | M13: 0.13943113 | N13: 0.14028221 | O13: 0.14113849 | P13: 0.142
A14: Canada | B14: =1-B12 -> 0.058 | C14: =B14*C10 -> 115.4193 | D14: =C14*(1+D13) -> 130.65465 | E14: =D14*(1+E13) -> 148.00634 | F14: =E14*(1+F13) -> 167.78241 | G14: =F14*(1+G13) -> 190.33773 | H14: =G14*(1+H13) -> 216.08138 | I14: =H14*(1+I13) -> 245.48533 | J14: =I14*(1+J13) -> 279.09442 | K14: =J14*(1+K13) -> 317.53811 | ... P14: =O14*(1+P13) -> 612.16189 | Q14: =RATE(9,,-G14,P14) -> 0.13860023
B15: =B14+B12 -> 1 | C15: =C14+C12 -> 1989.988
A16: Europe | B16: =B3 -> 0.25 | C16: =B16*E3 -> 1366.75 | D16: =D18+D20+D22+D24+D26+D28+D30+D32 -> 1520.4137 | E16: =E18+E20+E22+E24+E26+E28+E30+E32 -> 1693.4952 | F16: =F18+F20+F22+F24+F26+F28+F30+F32 -> 1888.6097 | G16: =G18+G20+G22+G24+G26+G28+G30+G32 -> 2108.7415 | H16: =H18+H20+H22+H24+H26+H28+H30+H32 -> 2357.2983 | I16: =I18+I20+I22+I24+I26+I28+I30+I32 -> 2638.1751 | J16: =J18+J20+J22+J24+J26+J28+J30+J32 -> 2955.8268 | K16: =K18+K20+K22+K24+K26+K28+K30+K32 -> 3315.3548 | ... P16: =P18+P20+P22+P24+P26+P28+P30+P32 -> 5978.9295 | Q16: =RATE(9,,-G16,P16) -> 0.12276509
D17: 0.152 | E17: 0.15114043 | F17: 0.15028572 | G17: 0.14943584 | H17: 0.14859077 | I17: 0.14775048 | J17: 0.14691494 | K17: 0.14608413 | L17: 0.14525801 | M17: 0.14443657 | N17: 0.14361977 | O17: 0.14280759 | P17: 0.142
A18: Germany (1) | B18: 0.25 | C18: =B18*C16 -> 341.6875 | D18: =C18*(1+D17) -> 393.624 | E18: =D18*(1+E17) -> 453.1165 | F18: =E18*(1+F17) -> 521.21344 | G18: =F18*(1+G17) -> 599.10141 | H18: =G18*(1+H17) -> 688.12235 | I18: =H18*(1+I17) -> 789.79276 | J18: =I18*(1+J17) -> 905.82511 | K18: =J18*(1+K17) -> 1038.1518 | ... P18: =O18*(1+P17) -> 2030.8451 | Q18: =RATE(9,,-G18,P18) -> 0.14527161
D19: 0.1265 | E19: 0.12809321 | F19: 0.12970648 | G19: 0.13134007 | H19: 0.13299423 | I19: 0.13466923 | J19: 0.13636532 | K19: 0.13808277 | L19: 0.13982186 | M19: 0.14158284 | N19: 0.14336601 | O19: 0.14517163 | P19: 0.147
A20: UK (2) | B20: 0.2 | C20: =B20*C16 -> 273.35 | D20: =C20*(1+D19) -> 307.92878 | E20: =D20*(1+E19) -> 347.37236 | F20: =E20*(1+F19) -> 392.4288 | G20: =F20*(1+G19) -> 443.97043 | H20: =G20*(1+H19) -> 503.01593 | I20: =H20*(1+I19) -> 570.7567 | J20: =I20*(1+J19) -> 648.58812 | K20: =J20*(1+K19) -> 738.14696 | ... P20: =O20*(1+P19) -> 1442.4691 | Q20: =RATE(9,,-G20,P20) -> 0.13988591
D21: 0.098 | E21: 0.098327255 | F21: 0.098655604 | G21: 0.098985048 | H21: 0.099315593 | I21: 0.099647242 | J21: 0.099979998 | K21: 0.10031387 | L21: 0.10064885 | M21: 0.10098495 | N21: 0.10132217 | O21: 0.10166052 | P21: 0.102
A22: France (3) | B22: 0.16 | C22: =B22*C16 -> 218.68 | D22: =C22*(1+D21) -> 240.11064 | E22: =D22*(1+E21) -> 263.72006 | F22: =E22*(1+F21) -> 289.73752 | G22: =F22*(1+G21) -> 318.4172 | H22: =G22*(1+H21) -> 350.041 | I22: =H22*(1+I21) -> 384.92162 | J22: =I22*(1+J21) -> 423.40608 | K22: =J22*(1+K21) -> 465.87958 | ... P22: =O22*(1+P21) -> 754.82731 | Q22: =RATE(9,,-G22,P22) -> 0.10065224
D23: 0.107 | E23: 0.10888874 | F23: 0.11081081 | G23: 0.11276682 | H23: 0.11475735 | I23: 0.11678301 | J23: 0.11884444 | K23: 0.12094225 | L23: 0.12307709 | M23: 0.12524961 | N23: 0.12746049 | O23: 0.12971039 | P23: 0.132
A24: Italy (4) | B24: 0.1 | C24: =B24*C16 -> 136.675 | D24: =C24*(1+D23) -> 151.29923 | E24: =D24*(1+E23) -> 167.77401 | F24: =E24*(1+F23) -> 186.36518 | G24: =F24*(1+G23) -> 207.38099 | H24: =G24*(1+H23) -> 231.17948 | I24: =H24*(1+I23) -> 258.17732 | J24: =I24*(1+J23) -> 288.86025 | K24: =J24*(1+K23) -> 323.79566 | ... P24: =O24*(1+P23) -> 589.98958 | Q24: =RATE(9,,-G24,P24) -> 0.12318895
D25: 0.075 | E25: 0.076287809 | F25: 0.077597731 | G25: 0.078930146 | H25: 0.080285439 | I25: 0.081664003 | J25: 0.083066239 | K25: 0.084492552 | L25: 0.085943356 | M25: 0.087419071 | N25: 0.088920125 | O25: 0.090446954 | P25: 0.092
A26: Spain (5) | B26: 0.05 | C26: =B26*C16 -> 68.3375 | D26: =C26*(1+D25) -> 73.462812 | E26: =D26*(1+E25) -> 79.06713 | F26: =E26*(1+F25) -> 85.202559 | G26: =F26*(1+G25) -> 91.92761 | H26: =G26*(1+H25) -> 99.308058 | I26: =H26*(1+I25) -> 107.41795 | J26: =I26*(1+J25) -> 116.34076 | K26: =J26*(1+K25) -> 126.17068 | ... P26: =O26*(1+P25) -> 193.19051 | Q26: =RATE(9,,-G26,P26) -> 0.086019835
D27: 0.056 | E27: 0.056477006 | F27: 0.056958075 | G27: 0.057443242 | H27: 0.057932541 | I27: 0.058426009 | J27: 0.058923679 | K27: 0.059425589 | L27: 0.059931774 | M27: 0.060442271 | N27: 0.060957116 | O27: 0.061476347 | P27: 0.062
A28: NORDIC | B28: 0.042 | C28: =B28*C16 -> 57.4035 | D28: =C28*(1+D27) -> 60.618096 | E28: =D28*(1+E27) -> 64.041625 | F28: =E28*(1+F27) -> 67.689312 | G28: =F28*(1+G27) -> 71.577606 | H28: =G28*(1+H27) -> 75.724278 | I28: =H28*(1+I27) -> 80.148546 | J28: =I28*(1+J27) -> 84.871193 | K28: =J28*(1+K27) -> 89.914714 | ... P28: =O28*(1+P27) -> 120.87274 | Q28: =RATE(9,,-G28,P28) -> 0.059945335
D29: 0.104 | E29: 0.10464426 | F29: 0.1052925 | G29: 0.10594477 | H29: 0.10660107 | I29: 0.10726144 | J29: 0.1079259 | K29: 0.10859448 | L29: 0.1092672 | M29: 0.10994408 | N29: 0.11062516 | O29: 0.11131046 | P29: 0.112
A30: Russia | B30: 0.062 | C30: =B30*C16 -> 84.7385 | D30: =C30*(1+D29) -> 93.551304 | E30: =D30*(1+E29) -> 103.34091 | F30: =E30*(1+F29) -> 114.22193 | G30: =F30*(1+G29) -> 126.32315 | H30: =G30*(1+H29) -> 139.78933 | I30: =H30*(1+I29) -> 154.78334 | J30: =I30*(1+J29) -> 171.48847 | K30: =J30*(1+K29) -> 190.11117 | ... P30: =O30*(1+P29) -> 321.257 | Q30: =RATE(9,,-G30,P30) -> 0.10927972
D31: 0.106 | E31: 0.10753783 | F31: 0.10909796 | G31: 0.11068074 | H31: 0.11228647 | I31: 0.1139155 | J31: 0.11556816 | K31: 0.1172448 | L31: 0.11894577 | M31: 0.12067141 | N31: 0.12242208 | O31: 0.12419816 | P31: 0.126
A32: Rest EU | B32: =1-SUM(B18+B20+B22+B24+B26+B28+B30) -> 0.136 | C32: =B32*C16 -> 185.878 | D32: =C32*(1+D25) -> 199.81885 | E32: =D32*(1+E25) -> 215.06259 | F32: =E32*(1+F25) -> 231.75096 | G32: =F32*(1+G25) -> 250.0431 | H32: =G32*(1+H25) -> 270.11792 | I32: =H32*(1+I25) -> 292.17683 | J32: =I32*(1+J25) -> 316.44686 | K32: =J32*(1+K25) -> 343.18426 | ... P32: =O32*(1+P25) -> 525.47818 | Q32: =RATE(9,,-G32,P32) -> 0.086019835
B33: =B18+B20+B22+B24+B26+B28+B30+B32 -> 1
A34: Latin America | B34: =B5 -> 0.1 | C34: =B34*E3 -> 546.7 | D34: =D36+D38+D42+D40 -> 612.44614 | E34: =E36+E38+E42+E40 -> 685.32809 | F34: =F36+F38+F42+F40 -> 768.2526 | G34: =G36+G38+G42+G40 -> 862.77822 | H34: =H36+H38+H42+H40 -> 970.73126 | I34: =I36+I38+I42+I40 -> 1094.2562 | J34: =J36+J38+J42+J40 -> 1235.8761 | K34: =K36+K38+K42+K40 -> 1398.5661 | ... P34: =P36+P38+P42+P40 -> 2676.6986 | Q34: =RATE(9,,-G34,P34) -> 0.13405304
D35: 0.103 | E35: 0.10467508 | F35: 0.1063774 | G35: 0.1081074 | H35: 0.10986554 | I35: 0.11165227 | J35: 0.11346806 | K35: 0.11531338 | L35: 0.1171887 | M35: 0.11909453 | N35: 0.12103135 | O35: 0.12299967 | P35: 0.125
A36: Brazil | B36: 0.24 | C36: =B36*C34 -> 131.208 | D36: =C36*(1+D29) -> 144.85363 | E36: =D36*(1+E35) -> 160.0162 | F36: =E36*(1+F35) -> 177.0383 | G36: =F36*(1+G35) -> 196.17745 | H36: =G36*(1+H35) -> 217.7306 | I36: =H36*(1+I35) -> 242.04071 | J36: =I36*(1+J35) -> 269.5046 | K36: =J36*(1+K35) -> 300.58209 | L36: =K36*(1+L35) -> 335.80691 | ... P36: =O36*(1+P35) -> 532.23853 | Q36: =RATE(9,,-G36,P36) -> 0.11727971
D37: 0.082 | E37: 0.082790089 | F37: 0.083587791 | G37: 0.084393179 | H37: 0.085206327 | I37: 0.08602731 | J37: 0.086856203 | K37: 0.087693083 | L37: 0.088538026 | M37: 0.089391111 | N37: 0.090252415 | O37: 0.091122018 | P37: 0.092
A38: Argentina | B38: 0.12 | C38: =B38*C34 -> 65.604 | D38: =C38*(1+D31) -> 72.558024 | E38: =D38*(1+E37) -> 78.565109 | F38: =E38*(1+F37) -> 85.132193 | G38: =F38*(1+G37) -> 92.31677 | H38: =G38*(1+H37) -> 100.18274 | I38: =H38*(1+I37) -> 108.80119 | J38: =I38*(1+J37) -> 118.25125 | K38: =J38*(1+K37) -> 128.62107 | L38: =K38*(1+L37) -> 140.00893 | ... P38: =O38*(1+P37) -> 198.13562 | Q38: =RATE(9,,-G38,P38) -> 0.088562958
D39: 0.152 | E39: 0.15429881 | F39: 0.15663238 | G39: 0.15900125 | H39: 0.16140594 | I39: 0.163847 | J39: 0.16632498 | K39: 0.16884044 | L39: 0.17139394 | M39: 0.17398605 | N39: 0.17661737 | O39: 0.17928849 | P39: 0.182
A40: Mexico | B40: 0.15 | C40: =B40*C34 -> 82.005 | D40: =C40*(1+D39) -> 94.46976 | E40: =D40*(1+E39) -> 109.04633 | F40: =E40*(1+F39) -> 126.12652 | G40: =F40*(1+G39) -> 146.18079 | H40: =G40*(1+H39) -> 169.77524 | I40: =H40*(1+I39) -> 197.59241 | J40: =I40*(1+J39) -> 230.45696 | K40: =J40*(1+K39) -> 269.36741 | ... P40: =O40*(1+P39) -> 607.55242 | Q40: =RATE(9,,-G40,P40) -> 0.17150384
...

Sheet North America
A2: North America Blood Culture Test Market, 2023-36 (USD Million)
D12: 2023 | E12: 2024 | F12: 2025 | G12: 2026 | H12: 2027 | I12: 2028 | J12: 2029 | K12: 2030 | L12: 2031 | M12: 2032 | N12: 2033 | O12: 2034 | P12: 2035 | Q12: 2036 | R12: CAGR (2024-2036)
D13: =D38+D64 -> 1989.988 | E13: =E38+E64 -> 2271.4121 | F13: =F38+F64 -> 2596.1078 | G13: =G38+G64 -> 2971.2332 | H13: =H38+H64 -> 3405.2109 | I13: =I38+I64 -> 3907.9649 | J13: =J38+J64 -> 4491.2043 | K13: =K38+K64 -> 5168.7645 | ... Q13: =Q38+Q64 -> 12380.481 | R13: =RATE(12,,-E13,Q13) -> 0.15178159 | T13: 2023 | U13: 2024 | V13: 2025 | W13: 2026 | X13: 2027 | Y13: 2028 | Z13: 2029 | AA13: 2030 | AB13: 2031 | AC13: 2032 | AD13: 2033 | AE13: 2034 | AF13: 2035 | AG13: 2036
A14: Test Type | B14: Phenotypic AST | D14: =D39+D65 -> 1114.3933 | E14: =E39+E65 -> 1274.0841 | F14: =F39+F65 -> 1458.6095 | G14: =G39+G65 -> 1672.1191 | H14: =H39+H65 -> 1919.5023 | I14: =I39+I65 -> 2206.5279 | J14: =J39+J65 -> 2540.0117 | K14: =K39+K65 -> 2928.0184 | ... Q14: =Q39+Q65 -> 7082.8733 | R14: =RATE(12,,-E14,Q14) -> 0.15367712 | S14: Phenotypic AST | T14: 0.56 | U14: 0.56092161 | V14: 0.56184474 | W14: 0.56276939 | X14: 0.56369557 | Y14: 0.56462326 | Z14: 0.56555248 | AA14: 0.56648323 | AB14: 0.56741552 | AC14: 0.56834934 | AD14: 0.56928469 | AE14: 0.57022158 | AF14: 0.57116002 | AG14: 0.5721
B15: Genotypic AST | D15: =D40+D66 -> 875.59472 | E15: =E40+E66 -> 997.32796 | F15: =F40+F66 -> 1137.4983 | G15: =G40+G66 -> 1299.1141 | H15: =H40+H66 -> 1485.7086 | I15: =I40+I66 -> 1701.437 | J15: =J40+J66 -> 1951.1926 | K15: =K40+K66 -> 2240.7461 | ... Q15: =Q40+Q66 -> 5297.6079 | R15: =RATE(12,,-E15,Q15) -> 0.14930903 | S15: Genotypic AST | T15: =1-T14 -> 0.44 | U15: =1-U14 -> 0.43907839 | V15: =1-V14 -> 0.43815526 | W15: =1-W14 -> 0.43723061 | X15: =1-X14 -> 0.43630443 | Y15: =1-Y14 -> 0.43537674 | Z15: =1-Z14 -> 0.43444752 | AA15: =1-AA14 -> 0.43351677 | ... AG15: =1-AG14 -> 0.4279
A17: Product | B17: Instruments | D17: =D42+D68 -> 937.28435 | E17: =E42+E68 -> 1068.4373 | F17: =F42+F68 -> 1219.5715 | G17: =G42+G68 -> 1393.9655 | H17: =H42+H68 -> 1595.4723 | I17: =I42+I68 -> 1828.6269 | J17: =J42+J68 -> 2098.7743 | K17: =K42+K68 -> 2412.2226 | ... Q17: =Q42+Q68 -> 5732.1628 | R17: =RATE(12,,-E17,Q17) -> 0.15026381 | S17: Instruments | T17: 0.471 | U17: 0.47038462 | V17: 0.46976923 | W17: 0.46915385 | X17: 0.46853846 | Y17: 0.46792308 | Z17: 0.46730769 | AA17: 0.46669231 | AB17: 0.46607692 | AC17: 0.46546154 | AD17: 0.46484615 | AE17: 0.46423077 | AF17: 0.46361538 | AG17: 0.463
B18: Consumables | D18: =D43+D69 -> 1052.7037 | E18: =E43+E69 -> 1202.9748 | F18: =F43+F69 -> 1376.5362 | G18: =G43+G69 -> 1577.2677 | H18: =H43+H69 -> 1809.7386 | I18: =I43+I69 -> 2079.3379 | J18: =J43+J69 -> 2392.43 | K18: =K43+K69 -> 2756.5419 | ... Q18: =Q43+Q69 -> 6648.3184 | R18: =RATE(12,,-E18,Q18) -> 0.15311142 | S18: Consumables | T18: =1-T17 -> 0.529 | U18: =1-U17 -> 0.52961538 | V18: =1-V17 -> 0.53023077 | W18: =1-W17 -> 0.53084615 | X18: =1-X17 -> 0.53146154 | Y18: =1-Y17 -> 0.53207692 | Z18: =1-Z17 -> 0.53269231 | AA18: =1-AA17 -> 0.53330769 | ... AG18: =1-AG17 -> 0.537
A20: Method | B20: Conventional | D20: =D45+D71 -> 797.98519 | E20: =E45+E71 -> 914.58614 | F20: =F45+F71 -> 1049.6287 | G20: =G45+G71 -> 1206.2408 | H20: =H45+H71 -> 1388.1155 | I20: =I45+I71 -> 1599.619 | J20: =J45+J71 -> 1845.9206 | K20: =K45+K71 -> 2133.1494 | ... Q20: =Q45+Q71 -> 5236.9435 | R20: =RATE(12,,-E20,Q20) -> 0.15652344 | S20: Conventional | T20: 0.401 | U20: 0.40265091 | V20: 0.40430861 | W20: 0.40597313 | X20: 0.40764451 | Y20: 0.40932277 | Z20: 0.41100794 | AA20: 0.41270005 | AB20: 0.41439913 | AC20: 0.4161052 | AD20: 0.41781829 | AE20: 0.41953843 | AF20: 0.42126566 | AG20: 0.423
B21: Automated | D21: =D46+D72 -> 1192.0028 | E21: =E46+E72 -> 1356.826 | F21: =F46+F72 -> 1546.479 | G21: =G46+G72 -> 1764.9923 | H21: =H46+H72 -> 2017.0954 | I21: =I46+I72 -> 2308.3458 | J21: =J46+J72 -> 2645.2836 | K21: =K46+K72 -> 3035.6151 | ... Q21: =Q46+Q72 -> 7143.5376 | R21: =RATE(12,,-E21,Q21) -> 0.14845972 | S21: Automated | T21: =1-T20 -> 0.599 | U21: =1-U20 -> 0.59734909 | V21: =1-V20 -> 0.59569139 | W21: =1-W20 -> 0.59402687 | X21: =1-X20 -> 0.59235549 | Y21: =1-Y20 -> 0.59067723 | Z21: =1-Z20 -> 0.58899206 | AA21: =1-AA20 -> 0.58729995 | ... AG21: =1-AG20 -> 0.577
A23: Technology | B23: Culture-Based | D23: =D48+D74 -> 497.497 | E23: =E48+E74 -> 571.3872 | F23: =F48+F74 -> 657.13083 | G23: =G48+G74 -> 756.76393 | H23: =H48+H74 -> 872.69455 | I23: =I48+I74 -> 1007.7747 | J23: =J48+J74 -> 1165.387 | K23: =K48+K74 -> 1349.5491 | ... Q23: =Q48+Q74 -> 3355.1104 | R23: =RATE(12,,-E23,Q23) -> 0.15894998 | S23: Culture-Based | T23: 0.25 | U23: 0.25155594 | V23: 0.25312155 | W23: 0.25469692 | X23: 0.25628209 | Y23: 0.25787712 | Z23: 0.25948208 | AA23: 0.26109703 | AB23: 0.26272203 | AC23: 0.26435714 | AD23: 0.26600243 | AE23: 0.26765796 | AF23: 0.2693238 | AG23: 0.271
B24: Molecular Technology | D24: =D49+D75 -> 756.19544 | E24: =E49+E75 -> 865.20333 | F24: =F49+F75 -> 991.25095 | G24: =G49+G75 -> 1137.1985 | H24: =H49+H75 -> 1306.4182 | I24: =I49+I75 -> 1502.8911 | J24: =J49+J75 -> 1731.3239 | K24: =K49+K75 -> 1997.289 | ... Q24: =Q49+Q75 -> 4853.1486 | R24: =RATE(12,,-E24,Q24) -> 0.15453947 | S24: Molecular Technology | T24: 0.38 | U24: 0.38090989 | V24: 0.38182196 | W24: 0.38273621 | X24: 0.38365265 | Y24: 0.38457129 | Z24: 0.38549212 | AA24: 0.38641516 | AB24: 0.38734041 | AC24: 0.38826788 | AD24: 0.38919756 | AE24: 0.39012948 | AF24: 0.39106362 | AG24: 0.392
B25: PCR | D25: =D50+D76 -> 264.6684 | E25: =E50+E76 -> 302.28983 | F25: =F50+F76 -> 345.72141 | G25: =G50+G76 -> 395.92804 | H25: =H50+H76 -> 454.04563 | I25: =I50+I76 -> 521.41329 | J25: =J50+J76 -> 599.61187 | K25: =K50+K76 -> 690.51023 | ... Q25: =Q50+Q76 -> 1660.2621 | R25: =RATE(12,,-E25,Q25) -> 0.15251369 | S25: PCR | T25: 0.35 | U25: 0.34938588 | V25: 0.34877285 | W25: 0.34816088 | X25: 0.34754999 | Y25: 0.34694018 | Z25: 0.34633143 | AA25: 0.34572375 | AB25: 0.34511714 | AC25: 0.34451159 | AD25: 0.3439071 | AE25: 0.34330368 | AF25: 0.34270131 | AG25: 0.3421
B26: Microarray | D26: =D51+D77 -> 211.73472 | E26: =E51+E77 -> 243.10413 | F26: =F51+F77 -> 279.4949 | G26: =G51+G77 -> 321.76788 | H26: =H51+H77 -> 370.94092 | I26: =I51+I77 -> 428.21921 | J26: =J51+J77 -> 495.03178 | K26: =K51+K77 -> 573.07543 | ... Q26: =Q51+Q77 -> 1421.9725 | R26: =RATE(12,,-E26,Q26) -> 0.15857701 | S26: Microarray | T26: 0.28 | U26: 0.28097919 | V26: 0.2819618 | W26: 0.28294785 | X26: 0.28393735 | Y26: 0.2849303 | Z26: 0.28592673 | AA26: 0.28692665 | AB26: 0.28793006 | AC26: 0.28893698 | AD26: 0.28994742 | AE26: 0.2909614 | AF26: 0.29197892 | AG26: 0.293
B27: PNA-FISH | D27: =D52+D78 -> 279.79231 | E27: =E52+E78 -> 319.80937 | F27: =F52+F78 -> 366.03463 | G27: =G52+G78 -> 419.50261 | H27: =H52+H78 -> 481.43164 | I27: =I52+I78 -> 553.25857 | J27: =J52+J78 -> 636.68022 | K27: =K52+K78 -> 733.70331 | ... Q27: =Q52+Q78 -> 1770.9139 | R27: =RATE(12,,-E27,Q27) -> 0.15329973 | S27: PNA-FISH | T27: =1-SUM(T25:T26) -> 0.37 | U27: =1-SUM(U25:U26) -> 0.36963493 | V27: =1-SUM(V25:V26) -> 0.36926535 | W27: =1-SUM(W25:W26) -> 0.36889127 | X27: =1-SUM(X25:X26) -> 0.36851266 | Y27: =1-SUM(Y25:Y26) -> 0.36812952 | Z27: =1-SUM(Z25:Z26) -> 0.36774184 | AA27: =1-SUM(AA25:AA26) -> 0.3673496 | ... AG27: =1-SUM(AG25:AG26) -> 0.3649
B28: Proteomic Technologies | D28: =D53+D79 -> 736.29556 | E28: =E53+E79 -> 834.82157 | F28: =F53+F79 -> 947.72598 | G28: =G53+G79 -> 1077.2707 | H28: =H53+H79 -> 1226.0982 | I28: =I53+I79 -> 1397.2991 | J28: =J53+J79 -> 1594.4934 | K28: =K53+K79 -> 1821.9265 | ... Q28: =Q53+Q79 -> 4172.2221 | R28: =RATE(12,,-E28,Q28) -> 0.14348678 | S28: Proteomic Technologies | T28: =1-SUM(T23+T24) -> 0.37 | U28: =1-SUM(U23+U24) -> 0.36753418 | V28: =1-SUM(V23+V24) -> 0.36505649 | W28: =1-SUM(W23+W24) -> 0.36256687 | X28: =1-SUM(X23+X24) -> 0.36006526 | Y28: =1-SUM(Y23+Y24) -> 0.3575516 | Z28: =1-SUM(Z23+Z24) -> 0.3550258 | AA28: =1-SUM(AA23+AA24) -> 0.35248781 | ... AG28: =1-SUM(AG23+AG24) -> 0.337
A30: Application | B30: Bacteremia | D30: =D55+D81 -> 797.98519 | E30: =E55+E81 -> 914.58614 | F30: =F55+F81 -> 1049.6287 | G30: =G55+G81 -> 1206.2408 | H30: =H55+H81 -> 1388.1155 | I30: =I55+I81 -> 1599.619 | J30: =J55+J81 -> 1845.9206 | K30: =K55+K81 -> 2133.1494 | ... Q30: =Q55+Q81 -> 5236.9435 | R30: =RATE(12,,-E30,Q30) -> 0.15652344 | S30: Bacteremia | T30: 0.401 | U30: 0.40265091 | V30: 0.40430861 | W30: 0.40597313 | X30: 0.40764451 | Y30: 0.40932277 | Z30: 0.41100794 | AA30: 0.41270005 | AB30: 0.41439913 | AC30: 0.4161052 | AD30: 0.41781829 | AE30: 0.41953843 | AF30: 0.42126566 | AG30: 0.423
B31: Fungemia | D31: =D56+D82 -> 857.68483 | E31: =E56+E82 -> 980.8783 | F31: =F56+F82 -> 1123.2692 | G31: =G56+G82 -> 1288.0709 | H31: =H56+H82 -> 1479.0709 | I31: =I56+I82 -> 1700.7385 | J31: =J56+J82 -> 1958.3559 | K31: =K56+K82 -> 2258.1744 | ... Q31: =Q56+Q82 -> 5472.1727 | R31: =RATE(12,,-E31,Q31) -> 0.1540166 | S31: Fungemia | T31: 0.431 | U31: 0.43183635 | V31: 0.43267432 | W31: 0.43351391 | X31: 0.43435514 | Y31: 0.43519799 | Z31: 0.43604249 | AA31: 0.43688862 | AB31: 0.43773639 | AC31: 0.43858581 | AD31: 0.43943688 | AE31: 0.4402896 | AF31: 0.44114397 | AG31: 0.442
B32: Mycobacterial Infection | D32: =D57+D83 -> 334.31798 | E32: =E57+E83 -> 375.94766 | F32: =F57+F83 -> 423.2099 | G32: =G57+G83 -> 476.92141 | H32: =H57+H83 -> 538.02451 | I32: =I57+I83 -> 607.60737 | J32: =J57+J83 -> 686.92776 | K32: =K57+K83 -> 777.44074 | ... Q32: =Q57+Q83 -> 1671.365 | R32: =RATE(12,,-E32,Q32) -> 0.13238817 | S32: Mycobacterial Infection | T32: =1-SUM(T30:T31) -> 0.168 | U32: =1-SUM(U30:U31) -> 0.16551275 | V32: =1-SUM(V30:V31) -> 0.16301708 | W32: =1-SUM(W30:W31) -> 0.16051295 | X32: =1-SUM(X30:X31) -> 0.15800035 | Y32: =1-SUM(Y30:Y31) -> 0.15547923 | Z32: =1-SUM(Z30:Z31) -> 0.15294957 | AA32: =1-SUM(AA30:AA31) -> 0.15041133 | ... AG32: =1-SUM(AG30:AG31) -> 0.135
A35: US Blood Culture Test Market
D37: 2023 | E37: 2024 | F37: 2025 | G37: 2026 | H37: 2027 | I37: 2028 | J37: 2029 | K37: 2030 | L37: 2031 | M37: 2032 | N37: 2033 | O37: 2034 | P37: 2035 | Q37: 2036 | R37: CAGR (2024-2036)
D38: ='Market Analysis'!C12 -> 1874.5687 | E38: ='Market Analysis'!D12 -> 2140.7575 | F38: ='Market Analysis'!E12 -> 2448.1014 | G38: ='Market Analysis'!F12 -> 2803.4508 | H38: ='Market Analysis'!G12 -> 3214.8732 | I38: ='Market Analysis'!H12 -> 3691.8835 | J38: ='Market Analysis'!I12 -> 4245.719 | K38: ='Market Analysis'!J12 -> 4889.6701 | ... Q38: ='Market Analysis'!P12 -> 11768.319 | R38: =RATE(12,,-E38,Q38) -> 0.15260079 | T38: 2023 | U38: 2024 | V38: 2025 | W38: 2026 | X38: 2027 | Y38: 2028 | Z38: 2029 | AA38: 2030 | AB38: 2031 | AC38: 2032 | AD38: 2033 | AE38: 2034 | AF38: 2035 | AG38: 2036
A39: Test Type | B39: Phenotypic AST | D39: =D38*T39 -> 1049.7585 | E39: =E38*U39 -> 1200.7971 | F39: =F38*V39 -> 1375.4529 | G39: =G38*W39 -> 1577.6963 | H39: =H38*X39 -> 1812.2098 | I39: =I38*Y39 -> 2084.5233 | J39: =J38*Z39 -> 2401.1769 | K39: =K38*AA39 -> 2769.9161 | ... Q39: =Q38*AG39 -> 6732.6554 | R39: =RATE(12,,-E39,Q39) -> 0.15449767 | S39: Phenotypic AST | T39: 0.56 | U39: 0.56092161 | V39: 0.56184474 | W39: 0.56276939 | X39: 0.56369557 | Y39: 0.56462326 | Z39: 0.56555248 | AA39: 0.56648323 | AB39: 0.56741552 | AC39: 0.56834934 | AD39: 0.56928469 | AE39: 0.57022158 | AF39: 0.57116002 | AG39: 0.5721
B40: Genotypic AST | D40: =D38*T40 -> 824.81023 | E40: =E38*U40 -> 939.96033 | F40: =F38*V40 -> 1072.6485 | G40: =G38*W40 -> 1225.7545 | H40: =H38*X40 -> 1402.6634 | I40: =I38*Y40 -> 1607.3602 | J40: =J38*Z40 -> 1844.5421 | K40: =K38*AA40 -> 2119.754 | ... Q40: =Q38*AG40 -> 5035.6638 | R40: =RATE(12,,-E40,Q40) -> 0.15012647 | S40: Genotypic AST | T40: =1-T39 -> 0.44 | U40: =1-U39 -> 0.43907839 | V40: =1-V39 -> 0.43815526 | W40: =1-W39 -> 0.43723061 | X40: =1-X39 -> 0.43630443 | Y40: =1-Y39 -> 0.43537674 | Z40: =1-Z39 -> 0.43444752 | AA40: =1-AA39 -> 0.43351677 | ... AG40: =1-AG39 -> 0.4279
A42: Product | B42: Instruments | D42: =D38*T42 -> 882.92186 | E42: =E38*U42 -> 1006.9794 | F42: =F38*V42 -> 1150.0427 | G42: =G38*W42 -> 1315.2497 | H42: =H38*X42 -> 1506.2917 | I42: =I38*Y42 -> 1727.5175 | J42: =J38*Z42 -> 1984.0571 | K42: =K38*AA42 -> 2281.9714 | ... Q42: =Q38*AG42 -> 5448.7318 | R42: =RATE(12,,-E42,Q42) -> 0.15108194 | S42: Instruments | T42: 0.471 | U42: 0.47038462 | V42: 0.46976923 | W42: 0.46915385 | X42: 0.46853846 | Y42: 0.46792308 | Z42: 0.46730769 | AA42: 0.46669231 | AB42: 0.46607692 | AC42: 0.46546154 | AD42: 0.46484615 | AE42: 0.46423077 | AF42: 0.46361538 | AG42: 0.463
B43: Consumables | D43: =D38*T43 -> 991.64684 | E43: =E38*U43 -> 1133.7781 | F43: =F38*V43 -> 1298.0587 | G43: =G38*W43 -> 1488.2011 | H43: =H38*X43 -> 1708.5814 | I43: =I38*Y43 -> 1964.366 | J43: =J38*Z43 -> 2261.6618 | K43: =K38*AA43 -> 2607.6987 | ... Q43: =Q38*AG43 -> 6319.5874 | R43: =RATE(12,,-E43,Q43) -> 0.15393157 | S43: Consumables | T43: =1-T42 -> 0.529 | U43: =1-U42 -> 0.52961538 | V43: =1-V42 -> 0.53023077 | W43: =1-W42 -> 0.53084615 | X43: =1-X42 -> 0.53146154 | Y43: =1-Y42 -> 0.53207692 | Z43: =1-Z42 -> 0.53269231 | AA43: =1-AA42 -> 0.53330769 | ... AG43: =1-AG42 -> 0.537
A45: Method | B45: Conventional | D45: =D38*T45 -> 751.70205 | E45: =E38*U45 -> 861.97793 | F45: =F38*V45 -> 989.78848 | G45: =G38*W45 -> 1138.1257 | H45: =H38*X45 -> 1310.5254 | I45: =I38*Y45 -> 1511.172 | J45: =J38*Z45 -> 1745.0242 | K45: =K38*AA45 -> 2017.9671 | ... Q45: =Q38*AG45 -> 4977.999 | R45: =RATE(12,,-E45,Q45) -> 0.15734602 | S45: Conventional | T45: 0.401 | U45: 0.40265091 | V45: 0.40430861 | W45: 0.40597313 | X45: 0.40764451 | Y45: 0.40932277 | Z45: 0.41100794 | AA45: 0.41270005 | AB45: 0.41439913 | AC45: 0.4161052 | AD45: 0.41781829 | AE45: 0.41953843 | AF45: 0.42126566 | AG45: 0.423
B46: Automated | D46: =D38*T46 -> 1122.8666 | E46: =E38*U46 -> 1278.7795 | F46: =F38*V46 -> 1458.3129 | G46: =G38*W46 -> 1665.3251 | H46: =H38*X46 -> 1904.3478 | I46: =I38*Y46 -> 2180.7115 | J46: =J38*Z46 -> 2500.6947 | K46: =K38*AA46 -> 2871.703 | ... Q46: =Q38*AG46 -> 6790.3202 | R46: =RATE(12,,-E46,Q46) -> 0.14927656 | S46: Automated | T46: =1-T45 -> 0.599 | U46: =1-U45 -> 0.59734909 | V46: =1-V45 -> 0.59569139 | W46: =1-W45 -> 0.59402687 | X46: =1-X45 -> 0.59235549 | Y46: =1-Y45 -> 0.59067723 | Z46: =1-Z45 -> 0.58899206 | AA46: =1-AA45 -> 0.58729995 | ... AG46: =1-AG45 -> 0.577
A48: Technology | B48: Culture-Based | D48: =D38*T48 -> 468.64217 | E48: =E38*U48 -> 538.52024 | F48: =F38*V48 -> 619.66724 | G48: =G38*W48 -> 714.03027 | H48: =H38*X48 -> 823.9144 | I48: =I38*Y48 -> 952.05227 | J48: =J38*Z48 -> 1101.688 | K48: =K38*AA48 -> 1276.6783 | ... Q48: =Q38*AG48 -> 3189.2145 | R48: =RATE(12,,-E48,Q48) -> 0.15977428 | S48: Culture-Based | T48: 0.25 | U48: 0.25155594 | V48: 0.25312155 | W48: 0.25469692 | X48: 0.25628209 | Y48: 0.25787712 | Z48: 0.25948208 | AA48: 0.26109703 | AB48: 0.26272203 | AC48: 0.26435714 | AD48: 0.26600243 | AE48: 0.26765796 | AF48: 0.2693238 | AG48: 0.271
B49: Molecular Technology | D49: =D38*T49 -> 712.3361 | E49: =E38*U49 -> 815.43568 | F49: =F38*V49 -> 934.73888 | G49: =G38*W49 -> 1072.9821 | H49: =H38*X49 -> 1233.3946 | I49: =I38*Y49 -> 1419.7924 | J49: =J38*Z49 -> 1636.6912 | K49: =K38*AA49 -> 1889.4427 | ... Q49: =Q38*AG49 -> 4613.1811 | R49: =RATE(12,,-E49,Q49) -> 0.15536064 | S49: Molecular Technology | T49: 0.38 | U49: 0.38090989 | V49: 0.38182196 | W49: 0.38273621 | X49: 0.38365265 | Y49: 0.38457129 | Z49: 0.38549212 | AA49: 0.38641516 | AB49: 0.38734041 | AC49: 0.38826788 | AD49: 0.38919756 | AE49: 0.39012948 | AF49: 0.39106362 | AG49: 0.392
B50: PCR | D50: =D49*T50 -> 249.31764 | E50: =E49*U50 -> 284.90172 | F50: =F49*V50 -> 326.01154 | G50: =G49*W50 -> 373.5704 | H50: =H49*X50 -> 428.66629 | I50: =I49*Y50 -> 492.58302 | J50: =J49*Z50 -> 566.8376 | K50: =K49*AA50 -> 653.2252 | ... Q50: =Q49*AG50 -> 1578.1693 | R50: =RATE(12,,-E50,Q50) -> 0.15333342 | S50: PCR | T50: 0.35 | U50: 0.34938588 | V50: 0.34877285 | W50: 0.34816088 | X50: 0.34754999 | Y50: 0.34694018 | Z50: 0.34633143 | AA50: 0.34572375 | AB50: 0.34511714 | AC50: 0.34451159 | AD50: 0.3439071 | AE50: 0.34330368 | AF50: 0.34270131 | AG50: 0.3421
B51: Microarray | D51: =D49*T51 -> 199.45411 | E51: =E49*U51 -> 229.12046 | F51: =F49*V51 -> 263.56066 | G51: =G49*W51 -> 303.59798 | H51: =H49*X51 -> 350.2068 | I51: =I49*Y51 -> 404.54187 | J51: =J49*Z51 -> 467.97377 | K51: =K49*AA51 -> 542.13145 | ... Q51: =Q49*AG51 -> 1351.6621 | R51: =RATE(12,,-E51,Q51) -> 0.15940105 | S51: Microarray | T51: 0.28 | U51: 0.28097919 | V51: 0.2819618 | W51: 0.28294785 | X51: 0.28393735 | Y51: 0.2849303 | Z51: 0.28592673 | AA51: 0.28692665 | AB51: 0.28793006 | AC51: 0.28893698 | AD51: 0.28994742 | AE51: 0.2909614 | AF51: 0.29197892 | AG51: 0.293
B52: PNA-FISH | D52: =D49*T52 -> 263.56436 | E52: =E49*U52 -> 301.41351 | F52: =F49*V52 -> 345.16668 | G52: =G49*W52 -> 395.81374 | H52: =H49*X52 -> 454.52153 | I52: =I49*Y52 -> 522.66749 | J52: =J49*Z52 -> 601.87983 | K52: =K49*AA52 -> 694.08601 | ... Q52: =Q49*AG52 -> 1683.3498 | R52: =RATE(12,,-E52,Q52) -> 0.15412001 | S52: PNA-FISH | T52: =1-SUM(T50:T51) -> 0.37 | U52: =1-SUM(U50:U51) -> 0.36963493 | V52: =1-SUM(V50:V51) -> 0.36926535 | W52: =1-SUM(W50:W51) -> 0.36889127 | X52: =1-SUM(X50:X51) -> 0.36851266 | Y52: =1-SUM(Y50:Y51) -> 0.36812952 | Z52: =1-SUM(Z50:Z51) -> 0.36774184 | AA52: =1-SUM(AA50:AA51) -> 0.3673496 | ... AG52: =1-SUM(AG50:AG51) -> 0.3649
B53: Proteomic Technologies | D53: =D38*T53 -> 693.59042 | E53: =E38*U53 -> 786.80152 | F53: =F38*V53 -> 893.69531 | G53: =G38*W53 -> 1016.4384 | H53: =H38*X53 -> 1157.5642 | I53: =I38*Y53 -> 1320.0388 | J53: =J38*Z53 -> 1507.3398 | K53: =K38*AA53 -> 1723.5491 | ... Q53: =Q38*AG53 -> 3965.9236 | R53: =RATE(12,,-E53,Q53) -> 0.14430008 | S53: Proteomic Technologies | T53: =1-SUM(T48+T49) -> 0.37 | U53: =1-SUM(U48+U49) -> 0.36753418 | V53: =1-SUM(V48+V49) -> 0.36505649 | W53: =1-SUM(W48+W49) -> 0.36256687 | X53: =1-SUM(X48+X49) -> 0.36006526 | Y53: =1-SUM(Y48+Y49) -> 0.3575516 | Z53: =1-SUM(Z48+Z49) -> 0.3550258 | AA53: =1-SUM(AA48+AA49) -> 0.35248781 | ... AG53: =1-SUM(AG48+AG49) -> 0.337
A55: Application | B55: Bacteremia | D55: =D38*T55 -> 751.70205 | E55: =E38*U55 -> 861.97793 | F55: =F38*V55 -> 989.78848 | G55: =G38*W55 -> 1138.1257 | H55: =H38*X55 -> 1310.5254 | I55: =I38*Y55 -> 1511.172 | J55: =J38*Z55 -> 1745.0242 | K55: =K38*AA55 -> 2017.9671 | ... Q55: =Q38*AG55 -> 4977.999 | R55: =RATE(12,,-E55,Q55) -> 0.15734602 | S55: Bacteremia | T55: 0.401 | U55: 0.40265091 | V55: 0.40430861 | W55: 0.40597313 | X55: 0.40764451 | Y55: 0.40932277 | Z55: 0.41100794 | AA55: 0.41270005 | AB55: 0.41439913 | AC55: 0.4161052 | AD55: 0.41781829 | AE55: 0.41953843 | AF55: 0.42126566 | AG55: 0.423
B56: Fungemia | D56: =D38*T56 -> 807.93911 | E56: =E38*U56 -> 924.45688 | F56: =F38*V56 -> 1059.2306 | G56: =G38*W56 -> 1215.3349 | H56: =H38*X56 -> 1396.3967 | I56: =I38*Y56 -> 1606.7003 | J56: =J38*Z56 -> 1851.3139 | K56: =K38*AA56 -> 2136.2412 | ... Q56: =Q38*AG56 -> 5201.5971 | R56: =RATE(12,,-E56,Q56) -> 0.15483739 | S56: Fungemia | T56: 0.431 | U56: 0.43183635 | V56: 0.43267432 | W56: 0.43351391 | X56: 0.43435514 | Y56: 0.43519799 | Z56: 0.43604249 | AA56: 0.43688862 | AB56: 0.43773639 | AC56: 0.43858581 | AD56: 0.43943688 | AE56: 0.4402896 | AF56: 0.44114397 | AG56: 0.442
B57: Mycobacterial Infection | D57: =D38*T57 -> 314.92754 | E57: =E38*U57 -> 354.32265 | F57: =F38*V57 -> 399.08234 | G57: =G38*W57 -> 449.99016 | H57: =H38*X57 -> 507.95109 | I57: =I38*Y57 -> 574.0112 | J57: =J38*Z57 -> 649.38088 | K57: =K38*AA57 -> 735.46178 | ... Q57: =Q38*AG57 -> 1588.7231 | R57: =RATE(12,,-E57,Q57) -> 0.13319359 | S57: Mycobacterial Infection | T57: =1-SUM(T55:T56) -> 0.168 | U57: =1-SUM(U55:U56) -> 0.16551275 | V57: =1-SUM(V55:V56) -> 0.16301708 | W57: =1-SUM(W55:W56) -> 0.16051295 | X57: =1-SUM(X55:X56) -> 0.15800035 | Y57: =1-SUM(Y55:Y56) -> 0.15547923 | Z57: =1-SUM(Z55:Z56) -> 0.15294957 | AA57: =1-SUM(AA55:AA56) -> 0.15041133 | ... AG57: =1-SUM(AG55:AG56) -> 0.135
A61: Canada Blood Culture Test Market
D63: 2023 | E63: 2024 | F63: 2025 | G63: 2026 | H63: 2027 | I63: 2028 | J63: 2029 | K63: 2030 | L63: 2031 | M63: 2032 | N63: 2033 | O63: 2034 | P63: 2035 | Q63: 2036 | R63: CAGR (2024-2036)
D64: ='Market Analysis'!C14 -> 115.4193 | E64: ='Market Analysis'!D14 -> 130.65465 | F64: ='Market Analysis'!E14 -> 148.00634 | G64: ='Market Analysis'!F14 -> 167.78241 | H64: ='Market Analysis'!G14 -> 190.33773 | I64: ='Market Analysis'!H14 -> 216.08138 | J64: ='Market Analysis'!I14 -> 245.48533 | K64: ='Market Analysis'!J14 -> 279.09442 | ... Q64: ='Market Analysis'!P14 -> 612.16189 | R64: =RATE(12,,-E64,Q64) -> 0.13735258 | T64: 2023 | U64: 2024 | V64: 2025 | W64: 2026 | X64: 2027 | Y64: 2028 | Z64: 2029 | AA64: 2030 | AB64: 2031 | AC64: 2032 | AD64: 2033 | AE64: 2034 | AF64: 2035 | AG64: 2036
A65: Test Type | B65: Phenotypic AST | D65: =D64*T65 -> 64.63481 | E65: =E64*U65 -> 73.287018 | F65: =F64*V65 -> 83.156583 | G65: =G64*W65 -> 94.422804 | H65: =H64*X65 -> 107.29253 | I65: =I64*Y65 -> 122.00458 | J65: =J64*Z65 -> 138.83484 | K65: =K64*AA65 -> 158.10231 | ... Q65: =Q64*AG65 -> 350.21781 | R65: =RATE(12,,-E65,Q65) -> 0.13922437 | S65: Phenotypic AST | T65: 0.56 | U65: 0.56092161 | V65: 0.56184474 | W65: 0.56276939 | X65: 0.56369557 | Y65: 0.56462326 | Z65: 0.56555248 | AA65: 0.56648323 | AB65: 0.56741552 | AC65: 0.56834934 | AD65: 0.56928469 | AE65: 0.57022158 | AF65: 0.57116002 | AG65: 0.5721
...

Sheet Global-
A2: Global Blood Culture Test Market, 2023-36 (USD Million)
D12: 2023 | E12: 2024 | F12: 2025 | G12: 2026 | H12: 2027 | I12: 2028 | J12: 2029 | K12: 2030 | L12: 2031 | M12: 2032 | N12: 2033 | O12: 2034 | P12: 2035 | Q12: 2036 | R12: CAGR (2024-2036)
D13: ='North America'!D13+Europe!D13+APAC!D13+'Latin America'!D13+MEA!D13 -> 5467 | E13: ='North America'!E13+Europe!E13+APAC!E13+'Latin America'!E13+MEA!E13 -> 6149.3791 | F13: ='North America'!F13+Europe!F13+APAC!F13+'Latin America'!F13+MEA!F13 -> 6913.5936 | G13: ='North America'!G13+Europe!G13+APAC!G13+'Latin America'!G13+MEA!G13 -> 7783.3528 | H13: ='North America'!H13+Europe!H13+APAC!H13+'Latin America'!H13+MEA!H13 -> 8774.4611 | I13: ='North America'!I13+Europe!I13+APAC!I13+'Latin America'!I13+MEA!I13 -> 9905.286 | J13: ='North America'!J13+Europe!J13+APAC!J13+'Latin America'!J13+MEA!J13 -> 11197.209 | K13: ='North America'!K13+Europe!K13+APAC!K13+'Latin America'!K13+MEA!K13 -> 12675.166 | ... Q13: ='North America'!Q13+Europe!Q13+APAC!Q13+'Latin America'!Q13+MEA!Q13 -> 27485.085 | R13: =RATE(12,,-E13,Q13) -> 0.1328928 | T13: 2023 | U13: 2024 | V13: 2025 | W13: 2026 | X13: 2027 | Y13: 2028 | Z13: 2029 | AA13: 2030 | AB13: 2031 | AC13: 2032 | AD13: 2033 | AE13: 2034 | AF13: 2035 | AG13: 2036
A14: Test Type | B14: Phenotypic AST | D14: ='North America'!D14+Europe!D14+APAC!D14+'Latin America'!D14+MEA!D14 -> 2950.0807 | E14: ='North America'!E14+Europe!E14+APAC!E14+'Latin America'!E14+MEA!E14 -> 3109.3205 | F14: ='North America'!F14+Europe!F14+APAC!F14+'Latin America'!F14+MEA!F14 -> 3508.1516 | G14: ='North America'!G14+Europe!G14+APAC!G14+'Latin America'!G14+MEA!G14 -> 3962.9554 | H14: ='North America'!H14+Europe!H14+APAC!H14+'Latin America'!H14+MEA!H14 -> 4482.1792 | I14: ='North America'!I14+Europe!I14+APAC!I14+'Latin America'!I14+MEA!I14 -> 5075.6436 | J14: ='North America'!J14+Europe!J14+APAC!J14+'Latin America'!J14+MEA!J14 -> 5754.7847 | K14: ='North America'!K14+Europe!K14+APAC!K14+'Latin America'!K14+MEA!K14 -> 6532.9424 | ... Q14: ='North America'!Q14+Europe!Q14+APAC!Q14+'Latin America'!Q14+MEA!Q14 -> 14370.512 | R14: =RATE(12,,-E14,Q14) -> 0.13605815 | S14: Phenotypic AST | T14: 0.56 | U14: 0.56092161 | V14: 0.56184474 | W14: 0.56276939 | X14: 0.56369557 | Y14: 0.56462326 | Z14: 0.56555248 | AA14: 0.56648323 | AB14: 0.56741552 | AC14: 0.56834934 | AD14: 0.56928469 | AE14: 0.57022158 | AF14: 0.57116002 | AG14: 0.5721
B15: Genotypic AST | D15: ='North America'!D15+Europe!D15+APAC!D15+'Latin America'!D15+MEA!D15 -> 2317.9205 | E15: ='North America'!E15+Europe!E15+APAC!E15+'Latin America'!E15+MEA!E15 -> 2433.9148 | F15: ='North America'!F15+Europe!F15+APAC!F15+'Latin America'!F15+MEA!F15 -> 2735.8359 | G15: ='North America'!G15+Europe!G15+APAC!G15+'Latin America'!G15+MEA!G15 -> 3078.9261 | H15: ='North America'!H15+Europe!H15+APAC!H15+'Latin America'!H15+MEA!H15 -> 3469.239 | I15: ='North America'!I15+Europe!I15+APAC!I15+'Latin America'!I15+MEA!I15 -> 3913.7905 | J15: ='North America'!J15+Europe!J15+APAC!J15+'Latin America'!J15+MEA!J15 -> 4420.7249 | K15: ='North America'!K15+Europe!K15+APAC!K15+'Latin America'!K15+MEA!K15 -> 4999.5126 | ... Q15: ='North America'!Q15+Europe!Q15+APAC!Q15+'Latin America'!Q15+MEA!Q15 -> 10748.369 | R15: =RATE(12,,-E15,Q15) -> 0.13175676 | S15: Genotypic AST | T15: =1-T14 -> 0.44 | U15: =1-U14 -> 0.43907839 | V15: =1-V14 -> 0.43815526 | W15: =1-W14 -> 0.43723061 | X15: =1-X14 -> 0.43630443 | Y15: =1-Y14 -> 0.43537674 | Z15: =1-Z14 -> 0.43444752 | AA15: =1-AA14 -> 0.43351677 | ... AG15: =1-AG14 -> 0.4279
A17: Product | B17: Instruments | D17: ='North America'!D17+Europe!D17+APAC!D17+'Latin America'!D17+MEA!D17 -> 2481.2286 | E17: ='North America'!E17+Europe!E17+APAC!E17+'Latin America'!E17+MEA!E17 -> 2607.4526 | F17: ='North America'!F17+Europe!F17+APAC!F17+'Latin America'!F17+MEA!F17 -> 2933.2332 | G17: ='North America'!G17+Europe!G17+APAC!G17+'Latin America'!G17+MEA!G17 -> 3303.7258 | H17: ='North America'!H17+Europe!H17+APAC!H17+'Latin America'!H17+MEA!H17 -> 3725.5453 | I17: ='North America'!I17+Europe!I17+APAC!I17+'Latin America'!I17+MEA!I17 -> 4206.3636 | J17: ='North America'!J17+Europe!J17+APAC!J17+'Latin America'!J17+MEA!J17 -> 4755.0939 | K17: ='North America'!K17+Europe!K17+APAC!K17+'Latin America'!K17+MEA!K17 -> 5382.108 | ... Q17: ='North America'!Q17+Europe!Q17+APAC!Q17+'Latin America'!Q17+MEA!Q17 -> 11630.042 | R17: =RATE(12,,-E17,Q17) -> 0.13269697 | S17: Instruments | T17: 0.471 | U17: 0.47038462 | V17: 0.46976923 | W17: 0.46915385 | X17: 0.46853846 | Y17: 0.46792308 | Z17: 0.46730769 | AA17: 0.46669231 | AB17: 0.46607692 | AC17: 0.46546154 | AD17: 0.46484615 | AE17: 0.46423077 | AF17: 0.46361538 | AG17: 0.463
B18: Consumables | D18: ='North America'!D18+Europe!D18+APAC!D18+'Latin America'!D18+MEA!D18 -> 2786.7726 | E18: ='North America'!E18+Europe!E18+APAC!E18+'Latin America'!E18+MEA!E18 -> 2935.7827 | F18: ='North America'!F18+Europe!F18+APAC!F18+'Latin America'!F18+MEA!F18 -> 3310.7543 | G18: ='North America'!G18+Europe!G18+APAC!G18+'Latin America'!G18+MEA!G18 -> 3738.1557 | H18: ='North America'!H18+Europe!H18+APAC!H18+'Latin America'!H18+MEA!H18 -> 4225.873 | I18: ='North America'!I18+Europe!I18+APAC!I18+'Latin America'!I18+MEA!I18 -> 4783.0704 | J18: ='North America'!J18+Europe!J18+APAC!J18+'Latin America'!J18+MEA!J18 -> 5420.4157 | K18: ='North America'!K18+Europe!K18+APAC!K18+'Latin America'!K18+MEA!K18 -> 6150.3469 | ... Q18: ='North America'!Q18+Europe!Q18+APAC!Q18+'Latin America'!Q18+MEA!Q18 -> 13488.839 | R18: =RATE(12,,-E18,Q18) -> 0.13550109 | S18: Consumables | T18: =1-T17 -> 0.529 | U18: =1-U17 -> 0.52961538 | V18: =1-V17 -> 0.53023077 | W18: =1-W17 -> 0.53084615 | X18: =1-X17 -> 0.53146154 | Y18: =1-Y17 -> 0.53207692 | Z18: =1-Z17 -> 0.53269231 | AA18: =1-AA17 -> 0.53330769 | ... AG18: =1-AG17 -> 0.537
A20: Method | B20: Conventional | D20: ='North America'!D20+Europe!D20+APAC!D20+'Latin America'!D20+MEA!D20 -> 2112.4685 | E20: ='North America'!E20+Europe!E20+APAC!E20+'Latin America'!E20+MEA!E20 -> 2231.9887 | F20: ='North America'!F20+Europe!F20+APAC!F20+'Latin America'!F20+MEA!F20 -> 2524.4979 | G20: ='North America'!G20+Europe!G20+APAC!G20+'Latin America'!G20+MEA!G20 -> 2858.8147 | H20: ='North America'!H20+Europe!H20+APAC!H20+'Latin America'!H20+MEA!H20 -> 3241.352 | I20: ='North America'!I20+Europe!I20+APAC!I20+'Latin America'!I20+MEA!I20 -> 3679.5801 | J20: ='North America'!J20+Europe!J20+APAC!J20+'Latin America'!J20+MEA!J20 -> 4182.2153 | K20: ='North America'!K20+Europe!K20+APAC!K20+'Latin America'!K20+MEA!K20 -> 4759.4448 | ... Q20: ='North America'!Q20+Europe!Q20+APAC!Q20+'Latin America'!Q20+MEA!Q20 -> 10625.286 | R20: =RATE(12,,-E20,Q20) -> 0.138861 | S20: Conventional | T20: 0.401 | U20: 0.40265091 | V20: 0.40430861 | W20: 0.40597313 | X20: 0.40764451 | Y20: 0.40932277 | Z20: 0.41100794 | AA20: 0.41270005 | AB20: 0.41439913 | AC20: 0.4161052 | AD20: 0.41781829 | AE20: 0.41953843 | AF20: 0.42126566 | AG20: 0.423
B21: Automated | D21: ='North America'!D21+Europe!D21+APAC!D21+'Latin America'!D21+MEA!D21 -> 3155.5327 | E21: ='North America'!E21+Europe!E21+APAC!E21+'Latin America'!E21+MEA!E21 -> 3311.2466 | F21: ='North America'!F21+Europe!F21+APAC!F21+'Latin America'!F21+MEA!F21 -> 3719.4896 | G21: ='North America'!G21+Europe!G21+APAC!G21+'Latin America'!G21+MEA!G21 -> 4183.0668 | H21: ='North America'!H21+Europe!H21+APAC!H21+'Latin America'!H21+MEA!H21 -> 4710.0662 | I21: ='North America'!I21+Europe!I21+APAC!I21+'Latin America'!I21+MEA!I21 -> 5309.854 | J21: ='North America'!J21+Europe!J21+APAC!J21+'Latin America'!J21+MEA!J21 -> 5993.2943 | K21: ='North America'!K21+Europe!K21+APAC!K21+'Latin America'!K21+MEA!K21 -> 6773.0102 | ... Q21: ='North America'!Q21+Europe!Q21+APAC!Q21+'Latin America'!Q21+MEA!Q21 -> 14493.594 | R21: =RATE(12,,-E21,Q21) -> 0.13092042 | S21: Automated | T21: =1-T20 -> 0.599 | U21: =1-U20 -> 0.59734909 | V21: =1-V20 -> 0.59569139 | W21: =1-W20 -> 0.59402687 | X21: =1-X20 -> 0.59235549 | Y21: =1-Y20 -> 0.59067723 | Z21: =1-Z20 -> 0.58899206 | AA21: =1-AA20 -> 0.58729995 | ... AG21: =1-AG20 -> 0.577
A23: Technology | B23: Culture-Based | D23: ='North America'!D23+Europe!D23+APAC!D23+'Latin America'!D23+MEA!D23 -> 1317.0003 | E23: ='North America'!E23+Europe!E23+APAC!E23+'Latin America'!E23+MEA!E23 -> 1394.4338 | F23: ='North America'!F23+Europe!F23+APAC!F23+'Latin America'!F23+MEA!F23 -> 1580.4878 | G23: ='North America'!G23+Europe!G23+APAC!G23+'Latin America'!G23+MEA!G23 -> 1793.5455 | H23: ='North America'!H23+Europe!H23+APAC!H23+'Latin America'!H23+MEA!H23 -> 2037.806 | I23: ='North America'!I23+Europe!I23+APAC!I23+'Latin America'!I23+MEA!I23 -> 2318.1693 | J23: ='North America'!J23+Europe!J23+APAC!J23+'Latin America'!J23+MEA!J23 -> 2640.3624 | K23: ='North America'!K23+Europe!K23+APAC!K23+'Latin America'!K23+MEA!K23 -> 3011.0897 | ... Q23: ='North America'!Q23+Europe!Q23+APAC!Q23+'Latin America'!Q23+MEA!Q23 -> 6807.2166 | R23: =RATE(12,,-E23,Q23) -> 0.14125048 | S23: Culture-Based | T23: 0.25 | U23: 0.25155594 | V23: 0.25312155 | W23: 0.25469692 | X23: 0.25628209 | Y23: 0.25787712 | Z23: 0.25948208 | AA23: 0.26109703 | AB23: 0.26272203 | AC23: 0.26435714 | AD23: 0.26600243 | AE23: 0.26765796 | AF23: 0.2693238 | AG23: 0.271
B24: Molecular Technology | D24: ='North America'!D24+Europe!D24+APAC!D24+'Latin America'!D24+MEA!D24 -> 2001.8405 | E24: ='North America'!E24+Europe!E24+APAC!E24+'Latin America'!E24+MEA!E24 -> 2111.4732 | F24: ='North America'!F24+Europe!F24+APAC!F24+'Latin America'!F24+MEA!F24 -> 2384.0915 | G24: ='North America'!G24+Europe!G24+APAC!G24+'Latin America'!G24+MEA!G24 -> 2695.1831 | H24: ='North America'!H24+Europe!H24+APAC!H24+'Latin America'!H24+MEA!H24 -> 3050.5827 | I24: ='North America'!I24+Europe!I24+APAC!I24+'Latin America'!I24+MEA!I24 -> 3457.0782 | J24: ='North America'!J24+Europe!J24+APAC!J24+'Latin America'!J24+MEA!J24 -> 3922.5788 | K24: ='North America'!K24+Europe!K24+APAC!K24+'Latin America'!K24+MEA!K24 -> 4456.3154 | ... Q24: ='North America'!Q24+Europe!Q24+APAC!Q24+'Latin America'!Q24+MEA!Q24 -> 9846.6011 | R24: =RATE(12,,-E24,Q24) -> 0.13690733 | S24: Molecular Technology | T24: 0.38 | U24: 0.38090989 | V24: 0.38182196 | W24: 0.38273621 | X24: 0.38365265 | Y24: 0.38457129 | Z24: 0.38549212 | AA24: 0.38641516 | AB24: 0.38734041 | AC24: 0.38826788 | AD24: 0.38919756 | AE24: 0.39012948 | AF24: 0.39106362 | AG24: 0.392
B25: PCR | D25: ='North America'!D25+Europe!D25+APAC!D25+'Latin America'!D25+MEA!D25 -> 700.64416 | E25: ='North America'!E25+Europe!E25+APAC!E25+'Latin America'!E25+MEA!E25 -> 737.71892 | F25: ='North America'!F25+Europe!F25+APAC!F25+'Latin America'!F25+MEA!F25 -> 831.50639 | G25: ='North America'!G25+Europe!G25+APAC!G25+'Latin America'!G25+MEA!G25 -> 938.35731 | H25: ='North America'!H25+Europe!H25+APAC!H25+'Latin America'!H25+MEA!H25 -> 1060.23 | I25: ='North America'!I25+Europe!I25+APAC!I25+'Latin America'!I25+MEA!I25 -> 1199.3993 | J25: ='North America'!J25+Europe!J25+APAC!J25+'Latin America'!J25+MEA!J25 -> 1358.5123 | K25: ='North America'!K25+Europe!K25+APAC!K25+'Latin America'!K25+MEA!K25 -> 1540.6541 | ... Q25: ='North America'!Q25+Europe!Q25+APAC!Q25+'Latin America'!Q25+MEA!Q25 -> 3368.5223 | R25: =RATE(12,,-E25,Q25) -> 0.13491249 | S25: PCR | T25: 0.35 | U25: 0.34938588 | V25: 0.34877285 | W25: 0.34816088 | X25: 0.34754999 | Y25: 0.34694018 | Z25: 0.34633143 | AA25: 0.34572375 | AB25: 0.34511714 | AC25: 0.34451159 | AD25: 0.3439071 | AE25: 0.34330368 | AF25: 0.34270131 | AG25: 0.3421
B26: Microarray | D26: ='North America'!D26+Europe!D26+APAC!D26+'Latin America'!D26+MEA!D26 -> 560.51533 | E26: ='North America'!E26+Europe!E26+APAC!E26+'Latin America'!E26+MEA!E26 -> 593.28002 | F26: ='North America'!F26+Europe!F26+APAC!F26+'Latin America'!F26+MEA!F26 -> 672.22274 | G26: ='North America'!G26+Europe!G26+APAC!G26+'Latin America'!G26+MEA!G26 -> 762.59625 | H26: ='North America'!H26+Europe!H26+APAC!H26+'Latin America'!H26+MEA!H26 -> 866.17435 | I26: ='North America'!I26+Europe!I26+APAC!I26+'Latin America'!I26+MEA!I26 -> 985.02635 | J26: ='North America'!J26+Europe!J26+APAC!J26+'Latin America'!J26+MEA!J26 -> 1121.5701 | K26: ='North America'!K26+Europe!K26+APAC!K26+'Latin America'!K26+MEA!K26 -> 1278.6357 | ... Q26: ='North America'!Q26+Europe!Q26+APAC!Q26+'Latin America'!Q26+MEA!Q26 -> 2885.0541 | R26: =RATE(12,,-E26,Q26) -> 0.14088321 | S26: Microarray | T26: 0.28 | U26: 0.28097919 | V26: 0.2819618 | W26: 0.28294785 | X26: 0.28393735 | Y26: 0.2849303 | Z26: 0.28592673 | AA26: 0.28692665 | AB26: 0.28793006 | AC26: 0.28893698 | AD26: 0.28994742 | AE26: 0.2909614 | AF26: 0.29197892 | AG26: 0.293
B27: PNA-FISH | D27: ='North America'!D27+Europe!D27+APAC!D27+'Latin America'!D27+MEA!D27 -> 740.68097 | E27: ='North America'!E27+Europe!E27+APAC!E27+'Latin America'!E27+MEA!E27 -> 780.47423 | F27: ='North America'!F27+Europe!F27+APAC!F27+'Latin America'!F27+MEA!F27 -> 880.3624 | G27: ='North America'!G27+Europe!G27+APAC!G27+'Latin America'!G27+MEA!G27 -> 994.22949 | H27: ='North America'!H27+Europe!H27+APAC!H27+'Latin America'!H27+MEA!H27 -> 1124.1783 | I27: ='North America'!I27+Europe!I27+APAC!I27+'Latin America'!I27+MEA!I27 -> 1272.6525 | J27: ='North America'!J27+Europe!J27+APAC!J27+'Latin America'!J27+MEA!J27 -> 1442.4963 | K27: ='North America'!K27+Europe!K27+APAC!K27+'Latin America'!K27+MEA!K27 -> 1637.0257 | ... Q27: ='North America'!Q27+Europe!Q27+APAC!Q27+'Latin America'!Q27+MEA!Q27 -> 3593.0248 | R27: =RATE(12,,-E27,Q27) -> 0.13568652 | S27: PNA-FISH | T27: =1-SUM(T25:T26) -> 0.37 | U27: =1-SUM(U25:U26) -> 0.36963493 | V27: =1-SUM(V25:V26) -> 0.36926535 | W27: =1-SUM(W25:W26) -> 0.36889127 | X27: =1-SUM(X25:X26) -> 0.36851266 | Y27: =1-SUM(Y25:Y26) -> 0.36812952 | Z27: =1-SUM(Z25:Z26) -> 0.36774184 | AA27: =1-SUM(AA25:AA26) -> 0.3673496 | ... AG27: =1-SUM(AG25:AG26) -> 0.3649
B28: Proteomic Technologies | D28: ='North America'!D28+Europe!D28+APAC!D28+'Latin America'!D28+MEA!D28 -> 1949.1604 | E28: ='North America'!E28+Europe!E28+APAC!E28+'Latin America'!E28+MEA!E28 -> 2037.3284 | F28: ='North America'!F28+Europe!F28+APAC!F28+'Latin America'!F28+MEA!F28 -> 2279.4081 | G28: ='North America'!G28+Europe!G28+APAC!G28+'Latin America'!G28+MEA!G28 -> 2553.153 | H28: ='North America'!H28+Europe!H28+APAC!H28+'Latin America'!H28+MEA!H28 -> 2863.0295 | I28: ='North America'!I28+Europe!I28+APAC!I28+'Latin America'!I28+MEA!I28 -> 3214.1865 | J28: ='North America'!J28+Europe!J28+APAC!J28+'Latin America'!J28+MEA!J28 -> 3612.5684 | K28: ='North America'!K28+Europe!K28+APAC!K28+'Latin America'!K28+MEA!K28 -> 4065.0498 | ... Q28: ='North America'!Q28+Europe!Q28+APAC!Q28+'Latin America'!Q28+MEA!Q28 -> 8465.0627 | R28: =RATE(12,,-E28,Q28) -> 0.12602343 | S28: Proteomic Technologies | T28: =1-SUM(T23+T24) -> 0.37 | U28: =1-SUM(U23+U24) -> 0.36753418 | V28: =1-SUM(V23+V24) -> 0.36505649 | W28: =1-SUM(W23+W24) -> 0.36256687 | X28: =1-SUM(X23+X24) -> 0.36006526 | Y28: =1-SUM(Y23+Y24) -> 0.3575516 | Z28: =1-SUM(Z23+Z24) -> 0.3550258 | AA28: =1-SUM(AA23+AA24) -> 0.35248781 | ... AG28: =1-SUM(AG23+AG24) -> 0.337
A30: Application | B30: Bacteremia | D30: ='North America'!D30+Europe!D30+APAC!D30+'Latin America'!D30+MEA!D30 -> 2112.4685 | E30: ='North America'!E30+Europe!E30+APAC!E30+'Latin America'!E30+MEA!E30 -> 2231.9887 | F30: ='North America'!F30+Europe!F30+APAC!F30+'Latin America'!F30+MEA!F30 -> 2524.4979 | G30: ='North America'!G30+Europe!G30+APAC!G30+'Latin America'!G30+MEA!G30 -> 2858.8147 | H30: ='North America'!H30+Europe!H30+APAC!H30+'Latin America'!H30+MEA!H30 -> 3241.352 | I30: ='North America'!I30+Europe!I30+APAC!I30+'Latin America'!I30+MEA!I30 -> 3679.5801 | J30: ='North America'!J30+Europe!J30+APAC!J30+'Latin America'!J30+MEA!J30 -> 4182.2153 | K30: ='North America'!K30+Europe!K30+APAC!K30+'Latin America'!K30+MEA!K30 -> 4759.4448 | ... Q30: ='North America'!Q30+Europe!Q30+APAC!Q30+'Latin America'!Q30+MEA!Q30 -> 10625.286 | R30: =RATE(12,,-E30,Q30) -> 0.138861 | S30: Bacteremia | T30: 0.401 | U30: 0.40265091 | V30: 0.40430861 | W30: 0.40597313 | X30: 0.40764451 | Y30: 0.40932277 | Z30: 0.41100794 | AA30: 0.41270005 | AB30: 0.41439913 | AC30: 0.4161052 | AD30: 0.41781829 | AE30: 0.41953843 | AF30: 0.42126566 | AG30: 0.423
B31: Fungemia | D31: ='North America'!D31+Europe!D31+APAC!D31+'Latin America'!D31+MEA!D31 -> 2270.5085 | E31: ='North America'!E31+Europe!E31+APAC!E31+'Latin America'!E31+MEA!E31 -> 2393.7705 | F31: ='North America'!F31+Europe!F31+APAC!F31+'Latin America'!F31+MEA!F31 -> 2701.613 | G31: ='North America'!G31+Europe!G31+APAC!G31+'Latin America'!G31+MEA!G31 -> 3052.7536 | H31: ='North America'!H31+Europe!H31+APAC!H31+'Latin America'!H31+MEA!H31 -> 3453.7393 | I31: ='North America'!I31+Europe!I31+APAC!I31+'Latin America'!I31+MEA!I31 -> 3912.1837 | J31: ='North America'!J31+Europe!J31+APAC!J31+'Latin America'!J31+MEA!J31 -> 4436.9545 | K31: ='North America'!K31+Europe!K31+APAC!K31+'Latin America'!K31+MEA!K31 -> 5038.3983 | ... Q31: ='North America'!Q31+Europe!Q31+APAC!Q31+'Latin America'!Q31+MEA!Q31 -> 11102.545 | R31: =RATE(12,,-E31,Q31) -> 0.13639244 | S31: Fungemia | T31: 0.431 | U31: 0.43183635 | V31: 0.43267432 | W31: 0.43351391 | X31: 0.43435514 | Y31: 0.43519799 | Z31: 0.43604249 | AA31: 0.43688862 | AB31: 0.43773639 | AC31: 0.43858581 | AD31: 0.43943688 | AE31: 0.4402896 | AF31: 0.44114397 | AG31: 0.442
B32: Mycobacterial Infection | D32: ='North America'!D32+Europe!D32+APAC!D32+'Latin America'!D32+MEA!D32 -> 885.0242 | E32: ='North America'!E32+Europe!E32+APAC!E32+'Latin America'!E32+MEA!E32 -> 917.47611 | F32: ='North America'!F32+Europe!F32+APAC!F32+'Latin America'!F32+MEA!F32 -> 1017.8766 | G32: ='North America'!G32+Europe!G32+APAC!G32+'Latin America'!G32+MEA!G32 -> 1130.3132 | H32: ='North America'!H32+Europe!H32+APAC!H32+'Latin America'!H32+MEA!H32 -> 1256.3269 | I32: ='North America'!I32+Europe!I32+APAC!I32+'Latin America'!I32+MEA!I32 -> 1397.6703 | J32: ='North America'!J32+Europe!J32+APAC!J32+'Latin America'!J32+MEA!J32 -> 1556.3398 | K32: ='North America'!K32+Europe!K32+APAC!K32+'Latin America'!K32+MEA!K32 -> 1734.6119 | ... Q32: ='North America'!Q32+Europe!Q32+APAC!Q32+'Latin America'!Q32+MEA!Q32 -> 3391.0489 | R32: =RATE(12,,-E32,Q32) -> 0.11509433 | S32: Mycobacterial Infection | T32: =1-SUM(T30:T31) -> 0.168 | U32: =1-SUM(U30:U31) -> 0.16551275 | V32: =1-SUM(V30:V31) -> 0.16301708 | W32: =1-SUM(W30:W31) -> 0.16051295 | X32: =1-SUM(X30:X31) -> 0.15800035 | Y32: =1-SUM(Y30:Y31) -> 0.15547923 | Z32: =1-SUM(Z30:Z31) -> 0.15294957 | AA32: =1-SUM(AA30:AA31) -> 0.15041133 | ... AG32: =1-SUM(AG30:AG31) -> 0.135

Sheet Europe
A2: Europe Blood Culture Test Market, 2023-36 (USD Million)
D12: 2023 | E12: 2024 | F12: 2025 | G12: 2026 | H12: 2027 | I12: 2028 | J12: 2029 | K12: 2030 | L12: 2031 | M12: 2032 | N12: 2033 | O12: 2034 | P12: 2035 | Q12: 2036 | R12: CAGR (2024-2036)
D13: =D38+D64+D90+D116+D142+D168+D194+D220 -> 1366.75 | E13: =E38+E64+E90+E116+E142+E168+E194+E220 -> 1520.4137 | F13: =F38+F64+F90+F116+F142+F168+F194+F220 -> 1693.4952 | G13: =G38+G64+G90+G116+G142+G168+G194+G220 -> 1888.6097 | H13: =H38+H64+H90+H116+H142+H168+H194+H220 -> 2108.7415 | I13: =I38+I64+I90+I116+I142+I168+I194+I220 -> 2357.2983 | J13: =J38+J64+J90+J116+J142+J168+J194+J220 -> 2638.1751 | K13: =K38+K64+K90+K116+K142+K168+K194+K220 -> 2955.8268 | ... Q13: =Q38+Q64+Q90+Q116+Q142+Q168+Q194+Q220 -> 5978.9295 | R13: =RATE(12,,-E13,Q13) -> 0.12086972 | T13: 2023 | U13: 2024 | V13: 2025 | W13: 2026 | X13: 2027 | Y13: 2028 | Z13: 2029 | AA13: 2030 | AB13: 2031 | AC13: 2032 | AD13: 2033 | AE13: 2034 | AF13: 2035 | AG13: 2036
A14: Test Type | B14: Phenotypic AST | D14: =D39+D65+D91+D117+D143+D169+D195+D221 -> 765.38 | E14: =E39+E65+E91+E117+E143+E169+E195+E221 -> 852.83291 | F14: =F39+F65+F91+F117+F143+F169+F195+F221 -> 951.48137 | G14: =G39+G65+G91+G117+G143+G169+G195+G221 -> 1062.8517 | H14: =H39+H65+H91+H117+H143+H169+H195+H221 -> 1188.6882 | I14: =I39+I65+I91+I117+I143+I169+I195+I221 -> 1330.9855 | J14: =J39+J65+J91+J117+J143+J169+J195+J221 -> 1492.0265 | K14: =K39+K65+K91+K117+K143+K169+K195+K221 -> 1674.4264 | ... Q14: =Q39+Q65+Q91+Q117+Q143+Q169+Q195+Q221 -> 3420.5456 | R14: =RATE(12,,-E14,Q14) -> 0.12271438 | S14: Phenotypic AST | T14: 0.56 | U14: 0.56092161 | V14: 0.56184474 | W14: 0.56276939 | X14: 0.56369557 | Y14: 0.56462326 | Z14: 0.56555248 | AA14: 0.56648323 | AB14: 0.56741552 | AC14: 0.56834934 | AD14: 0.56928469 | AE14: 0.57022158 | AF14: 0.57116002 | AG14: 0.5721
B15: Genotypic AST | D15: =D40+D66+D92+D118+D144+D170+D196+D222 -> 601.37 | E15: =E40+E66+E92+E118+E144+E170+E196+E222 -> 667.5808 | F15: =F40+F66+F92+F118+F144+F170+F196+F222 -> 742.01382 | G15: =G40+G66+G92+G118+G144+G170+G196+G222 -> 825.75797 | H15: =H40+H66+H92+H118+H144+H170+H196+H222 -> 920.05327 | I15: =I40+I66+I92+I118+I144+I170+I196+I222 -> 1026.3129 | J15: =J40+J66+J92+J118+J144+J170+J196+J222 -> 1146.1486 | K15: =K40+K66+K92+K118+K144+K170+K196+K222 -> 1281.4005 | ... Q15: =Q40+Q66+Q92+Q118+Q144+Q170+Q196+Q222 -> 2558.3839 | R15: =RATE(12,,-E15,Q15) -> 0.11846352 | S15: Genotypic AST | T15: =1-T14 -> 0.44 | U15: =1-U14 -> 0.43907839 | V15: =1-V14 -> 0.43815526 | W15: =1-W14 -> 0.43723061 | X15: =1-X14 -> 0.43630443 | Y15: =1-Y14 -> 0.43537674 | Z15: =1-Z14 -> 0.43444752 | AA15: =1-AA14 -> 0.43351677 | ... AG15: =1-AG14 -> 0.4279
A17: Product | B17: Instruments | D17: =D42+D68+D94+D120+D146+D172+D198+D224 -> 643.73925 | E17: =E42+E68+E94+E120+E146+E172+E198+E224 -> 715.17921 | F17: =F42+F68+F94+F120+F146+F172+F198+F224 -> 795.55193 | G17: =G42+G68+G94+G120+G146+G172+G198+G224 -> 886.04851 | H17: =H42+H68+H94+H120+H146+H172+H198+H224 -> 988.0265 | I17: =I42+I68+I94+I120+I146+I172+I198+I224 -> 1103.0343 | J17: =J42+J68+J94+J120+J146+J172+J198+J224 -> 1232.8395 | K17: =K42+K68+K94+K120+K146+K172+K198+K224 -> 1379.4617 | ... Q17: =Q42+Q68+Q94+Q120+Q146+Q172+Q198+Q224 -> 2768.2444 | R17: =RATE(12,,-E17,Q17) -> 0.11939268 | S17: Instruments | T17: 0.471 | U17: 0.47038462 | V17: 0.46976923 | W17: 0.46915385 | X17: 0.46853846 | Y17: 0.46792308 | Z17: 0.46730769 | AA17: 0.46669231 | AB17: 0.46607692 | AC17: 0.46546154 | AD17: 0.46484615 | AE17: 0.46423077 | AF17: 0.46361538 | AG17: 0.463
B18: Consumables | D18: =D43+D69+D95+D121+D147+D173+D199+D225 -> 723.01075 | E18: =E43+E69+E95+E121+E147+E173+E199+E225 -> 805.23449 | F18: =F43+F69+F95+F121+F147+F173+F199+F225 -> 897.94325 | G18: =G43+G69+G95+G121+G147+G173+G199+G225 -> 1002.5612 | H18: =H43+H69+H95+H121+H147+H173+H199+H225 -> 1120.715 | I18: =I43+I69+I95+I121+I147+I173+I199+I225 -> 1254.2641 | J18: =J43+J69+J95+J121+J147+J173+J199+J225 -> 1405.3356 | K18: =K43+K69+K95+K121+K147+K173+K199+K225 -> 1576.3652 | ... Q18: =Q43+Q69+Q95+Q121+Q147+Q173+Q199+Q225 -> 3210.6852 | R18: =RATE(12,,-E18,Q18) -> 0.12216386 | S18: Consumables | T18: =1-T17 -> 0.529 | U18: =1-U17 -> 0.52961538 | V18: =1-V17 -> 0.53023077 | W18: =1-W17 -> 0.53084615 | X18: =1-X17 -> 0.53146154 | Y18: =1-Y17 -> 0.53207692 | Z18: =1-Z17 -> 0.53269231 | AA18: =1-AA17 -> 0.53330769 | ... AG18: =1-AG17 -> 0.537
A20: Method | B20: Conventional | D20: =D45+D71+D97+D123+D149+D175+D201+D227 -> 548.06675 | E20: =E45+E71+E97+E123+E149+E175+E201+E227 -> 612.19595 | F20: =F45+F71+F97+F123+F149+F175+F201+F227 -> 684.69468 | G20: =G45+G71+G97+G123+G149+G175+G201+G227 -> 766.7248 | H20: =H45+H71+H97+H123+H149+H175+H201+H227 -> 859.6169 | I20: =I45+I71+I97+I123+I149+I175+I201+I227 -> 964.8959 | J20: =J45+J71+J97+J123+J149+J175+J201+J227 -> 1084.3109 | K20: =K45+K71+K97+K123+K149+K175+K201+K227 -> 1219.8699 | ... Q20: =Q45+Q71+Q97+Q123+Q149+Q175+Q201+Q227 -> 2529.0872 | R20: =RATE(12,,-E20,Q20) -> 0.12548431 | S20: Conventional | T20: 0.401 | U20: 0.40265091 | V20: 0.40430861 | W20: 0.40597313 | X20: 0.40764451 | Y20: 0.40932277 | Z20: 0.41100794 | AA20: 0.41270005 | AB20: 0.41439913 | AC20: 0.4161052 | AD20: 0.41781829 | AE20: 0.41953843 | AF20: 0.42126566 | AG20: 0.423
B21: Automated | D21: =D46+D72+D98+D124+D150+D176+D202+D228 -> 818.68325 | E21: =E46+E72+E98+E124+E150+E176+E202+E228 -> 908.21775 | F21: =F46+F72+F98+F124+F150+F176+F202+F228 -> 1008.8005 | G21: =G46+G72+G98+G124+G150+G176+G202+G228 -> 1121.8849 | H21: =H46+H72+H98+H124+H150+H176+H202+H228 -> 1249.1246 | I21: =I46+I72+I98+I124+I150+I176+I202+I228 -> 1392.4024 | J21: =J46+J72+J98+J124+J150+J176+J202+J228 -> 1553.8641 | K21: =K46+K72+K98+K124+K150+K176+K202+K228 -> 1735.957 | ... Q21: =Q46+Q72+Q98+Q124+Q150+Q176+Q202+Q228 -> 3449.8423 | R21: =RATE(12,,-E21,Q21) -> 0.117637 | S21: Automated | T21: =1-T20 -> 0.599 | U21: =1-U20 -> 0.59734909 | V21: =1-V20 -> 0.59569139 | W21: =1-W20 -> 0.59402687 | X21: =1-X20 -> 0.59235549 | Y21: =1-Y20 -> 0.59067723 | Z21: =1-Z20 -> 0.58899206 | AA21: =1-AA20 -> 0.58729995 | ... AG21: =1-AG20 -> 0.577
A23: Technology | B23: Culture-Based | D23: =D48+D74+D100+D126+D152+D178+D204+D230 -> 341.6875 | E23: =E48+E74+E100+E126+E152+E178+E204+E230 -> 382.46909 | F23: =F48+F74+F100+F126+F152+F178+F204+F230 -> 428.66013 | G23: =G48+G74+G100+G126+G152+G178+G204+G230 -> 481.02307 | H23: =H48+H74+H100+H126+H152+H178+H204+H230 -> 540.43267 | I23: =I48+I74+I100+I126+I152+I178+I204+I230 -> 607.89331 | J23: =J48+J74+J100+J126+J152+J178+J204+J230 -> 684.55915 | K23: =K48+K74+K100+K126+K152+K178+K204+K230 -> 771.75761 | ... Q23: =Q48+Q74+Q100+Q126+Q152+Q178+Q204+Q230 -> 1620.2899 | R23: =RATE(12,,-E23,Q23) -> 0.12784573 | S23: Culture-Based | T23: 0.25 | U23: 0.25155594 | V23: 0.25312155 | W23: 0.25469692 | X23: 0.25628209 | Y23: 0.25787712 | Z23: 0.25948208 | AA23: 0.26109703 | AB23: 0.26272203 | AC23: 0.26435714 | AD23: 0.26600243 | AE23: 0.26765796 | AF23: 0.2693238 | AG23: 0.271
B24: Molecular Technology | D24: =D49+D75+D101+D127+D153+D179+D205+D231 -> 519.365 | E24: =E49+E75+E101+E127+E153+E179+E205+E231 -> 579.14062 | F24: =F49+F75+F101+F127+F153+F179+F205+F231 -> 646.61365 | G24: =G49+G75+G101+G127+G153+G179+G205+G231 -> 722.83932 | H24: =H49+H75+H101+H127+H153+H179+H205+H231 -> 809.02426 | I24: =I49+I75+I101+I127+I153+I179+I205+I231 -> 906.54926 | J24: =J49+J75+J101+J127+J153+J179+J205+J231 -> 1016.9957 | K24: =K49+K75+K101+K127+K153+K179+K205+K231 -> 1142.1763 | ... Q24: =Q49+Q75+Q101+Q127+Q153+Q179+Q205+Q231 -> 2343.7404 | R24: =RATE(12,,-E24,Q24) -> 0.12355359 | S24: Molecular Technology | T24: 0.38 | U24: 0.38090989 | V24: 0.38182196 | W24: 0.38273621 | X24: 0.38365265 | Y24: 0.38457129 | Z24: 0.38549212 | AA24: 0.38641516 | AB24: 0.38734041 | AC24: 0.38826788 | AD24: 0.38919756 | AE24: 0.39012948 | AF24: 0.39106362 | AG24: 0.392
B25: PCR | D25: =D50+D76+D102+D128+D154+D180+D206+D232 -> 181.77775 | E25: =E50+E76+E102+E128+E154+E180+E206+E232 -> 202.34356 | F25: =F50+F76+F102+F128+F154+F180+F206+F232 -> 225.52128 | G25: =G50+G76+G102+G128+G154+G180+G206+G232 -> 251.66438 | H25: =H50+H76+H102+H128+H154+H180+H206+H232 -> 281.17638 | I25: =I50+I76+I102+I128+I154+I180+I206+I232 -> 314.51836 | J25: =J50+J76+J102+J128+J154+J180+J206+J232 -> 352.21757 | K25: =K50+K76+K102+K128+K154+K180+K206+K232 -> 394.87748 | ... Q25: =Q50+Q76+Q102+Q128+Q154+Q180+Q206+Q232 -> 801.79358 | R25: =RATE(12,,-E25,Q25) -> 0.12158218 | S25: PCR | T25: 0.35 | U25: 0.34938588 | V25: 0.34877285 | W25: 0.34816088 | X25: 0.34754999 | Y25: 0.34694018 | Z25: 0.34633143 | AA25: 0.34572375 | AB25: 0.34511714 | AC25: 0.34451159 | AD25: 0.3439071 | AE25: 0.34330368 | AF25: 0.34270131 | AG25: 0.3421
